Workbook

Sheet Overview
A1: FitMatch size-chart data (v8) — brands, sources and status
A2: Every number in 'All measurements' traces back to a brand's published size guide or to a stated formula. Generated from data/size_charts.json.
A4: Assumptions
A5: Zara ease subtracted (cm) | B5: 12 | C5: FitMatch's true-fit garment chest ease (6 cm flat) × 2. Body chest ≈ flat chest × 2 − this.
A6: Inches to cm | B6: 2.54 | C6: Used where a chart was published in inches (Lulu & Sky).
A8: Summary
A9: Status | B9: Women's charts | C9: Men's charts | D9: Total | E9: Meaning
A10: Sourced | B10: =COUNTIFS(D$17:D$60,"Women",C$17:C$60,A10) -> 12 | C10: =COUNTIFS(D$17:D$60,"Men",C$17:C$60,A10) -> 11 | D10: =B10+C10 -> 23 | E10: From a published size guide (the brand's own, or Levi's via retailer copies of its US chart)
A11: Approximate | B11: =COUNTIFS(D$17:D$60,"Women",C$17:C$60,A11) -> 1 | C11: =COUNTIFS(D$17:D$60,"Men",C$17:C$60,A11) -> 1 | D11: =B11+C11 -> 2 | E11: Converted from one product's garment chart; confidence capped at medium in the app
A12: Unverified | B12: =COUNTIFS(D$17:D$60,"Women",C$17:C$60,A12) -> 1 | C12: =COUNTIFS(D$17:D$60,"Men",C$17:C$60,A12) -> 0 | D12: =B12+C12 -> 1 | E12: From a third-party site that can't be checked against the brand
A13: Placeholder | B13: =COUNTIFS(D$17:D$60,"Women",C$17:C$60,A13) -> 0 | C13: =COUNTIFS(D$17:D$60,"Men",C$17:C$60,A13) -> 1 | D13: =B13+C13 -> 1 | E13: Invented: average of the real men's charts; labelled in the app
A14: Total | B14: =SUM(B10:B13) -> 14 | C14: =SUM(C10:C13) -> 13 | D14: =SUM(D10:D13) -> 27
A15: Brands
A16: Brand | B16: Sizes | C16: Status | D16: Gender | E16: Measurements used | F16: Stored rows | G16: Source (from the data file)
A17: Adidas | B17: XXS–4XL | C17: Sourced | D17: Women | E17: bust, waist, hip | F17: =COUNTIFS('All measurements'!A$5:A$418,D17,'All measurements'!B$5:B$418,A17) -> 27 | G17: adidas size-guide popup (women's tops, standard sizes; screenshot supplied by the user): bust, waist and hip in cm ranges, stored as range midpoints. Standard sizes only (no Tall/Petite/Plus). Size labels 2XS..2XL stored as XXS..XXL. Plus sizes: adidas 'Plus size' table 3X and 4X stored as 3XL and 4XL (1X and 2X not stored: they overlap standard XL/XXL).
A18: H&M | B18: XXS–4XL | C18: Sourced | D18: Women | E18: bust, waist, hip | F18: =COUNTIFS('All measurements'!A$5:A$418,D18,'All measurements'!B$5:B$418,A18) -> 27 | G18: H&M size-guide popup, women's Regular tab (chest / waist / low hip, cm ranges; screenshot supplied by the user). Stored as range midpoints. 'Low hip' stored as hip, which is an approximation. Maternity tab not used. The page advises going down a size for its oversized tee.
A19: Levi's | B19: XXS–3XL | C19: Sourced | D19: Women | E19: bust, waist, hip | F19: =COUNTIFS('All measurements'!A$5:A$418,D19,'All measurements'!B$5:B$418,A19) -> 24 | G19: Levi's US women's tops & outerwear chart as reproduced by retailers (hibbett.com, scheels.com); inches converted to cm. Not taken from levi.com directly. The two retailers disagree on size L waist/hip (scheels shows the M values); hibbett's internally consistent values are used. Not yet checked against Levi's India. Plus: the 3X row stored as 3XL (1X and 2X not stored: they overlap standard XL/XXL). No 4X on this chart.
A20: Lulu & Sky | B20: S–XL | C20: Sourced | D20: Women | E20: bust, waist | F20: =COUNTIFS('All measurements'!A$5:A$418,D20,'All measurements'!B$5:B$418,A20) -> 8 | G20: Lulu & Sky size guide labelled 'Body Measurement (inches)' (screenshot supplied by the user); converted to cm. Two quirks: S to M steps only 1 inch (others 2-3), and its 'length' column (12-13 in) is a garment measurement, probably of a crop top, so it is not used. A second Lulu & Sky chart (M-2XL, with sleeve and hem width) is a per-product garment chart and is not used.
A21: Marks & Spencer | B21: XS–XXL | C21: Sourced | D21: Women | E21: bust, waist | F21: =COUNTIFS('All measurements'!A$5:A$418,D21,'All measurements'!B$5:B$418,A21) -> 12 | G21: M&S India women's Tops size guide (UK sizes 6-30, body bust and waist in cm; screenshot supplied by the user). Converted to letters with M&S's own dual-size row (XS=6, S=8-10, M=12-14, L=16-18, XL=20-22, XXL=24-26) by averaging each pair. The dual-size row is stated to be for jerseys and knitted dresses. XXXL (28-30) NOT stored: the published bust row lists 132 for both 26 and 28, while every other step (and the waist row) rises by 6, so the top of the bust row looks shifted. No hip on this chart.
A22: Max | B22: XS–4XL | C22: Sourced | D22: Women | E22: bust, waist | F22: =COUNTIFS('All measurements'!A$5:A$418,D22,'All measurements'!B$5:B$418,A22) -> 16 | G22: Max (maxfashion.in) women's chart from the Metallic printed product, 'Above size chart is for body measurements' (cm; screenshot supplied by the user). 5XL and 6XL are published but not stored (beyond 4XL). The step from XXL to 3XL is uneven (bust +8, waist +14, shoulder actually drops), which looks like a separate plus-size block. A second Max product (URB_N oversized) shows the same numbers shifted one size smaller; the main Max label was chosen. Chest column stored as bust; shoulder not used.
A23: Nike | B23: XS–XXL | C23: Sourced | D23: Women | E23: bust, waist, hip | F23: =COUNTIFS('All measurements'!A$5:A$418,D23,'All measurements'!B$5:B$418,A23) -> 18 | G23: nike.in size guide, 'body measurements this product fits' (screenshots supplied by the user). Identical on the Sportswear Slim Mod-Cropped tee and the Sportswear regular tee, so treated as Nike's women's chart. Stored as range midpoints; '2XL' stored as XXL. The Jordan oversized tee shows a different, wider chart (Jordan label) and is not used.
A24: Pantaloons | B24: XS–XXL | C24: Sourced | D24: Women | E24: bust, waist, hip | F24: =COUNTIFS('All measurements'!A$5:A$418,D24,'All measurements'!B$5:B$418,A24) -> 18 | G24: Pantaloons size-chart popups, 'All measurements are body measurements' (cm; screenshots supplied by the user). Identical on the Annabelle top and the SF Jeans oversized tee; the user checked other products and found the same chart. Single values (inch sizes converted), not ranges. Shoulder is published but not used. '2XL' stored as XXL.
A25: Red Tape | B25: XS–XL | C25: Sourced | D25: Women | E25: bust | F25: =COUNTIFS('All measurements'!A$5:A$418,D25,'All measurements'!B$5:B$418,A25) -> 5 | G25: Red Tape size-chart popup on a women's tee (screenshot supplied by the user). The 'Standard Size' column (32-40 in) is read as body bust; the page does not say so, but the user confirmed the column is the same across products. Garment columns (chest all round, shoulder, length) not used.
A26: The Souled Store | B26: XXS–XXL | C26: Sourced | D26: Women | E26: bust | F26: =COUNTIFS('All measurements'!A$5:A$418,D26,'All measurements'!B$5:B$418,A26) -> 7 | G26: The Souled Store size charts, 'To fit your bust size' column (cm; screenshots supplied by the user). The column is identical on the women's fitted, oversized and polo charts, so it is treated as the brand's body chart. Single values, not ranges; the page doesn't say whether each is a midpoint or a lower bound. Garment columns not used here.
A27: Uniqlo | B27: S–3XL | C27: Sourced | D27: Women | E27: bust, waist, hip | F27: =COUNTIFS('All measurements'!A$5:A$418,D27,'All measurements'!B$5:B$418,A27) -> 18 | G27: Uniqlo India body-size chart for the basic tee line (bust / waist / hip, cm ranges; screenshot supplied by the user). Stored as range midpoints. Uniqlo's body chart differs by product line: the UNIQLO:C long-sleeve line runs about 6 cm larger in bust (S 83-89), so this is one line's chart, not the only one.
A28: Westside | B28: XXS–XXL | C28: Sourced | D28: Women | E28: bust, waist, hip | F28: =COUNTIFS('All measurements'!A$5:A$418,D28,'All measurements'!B$5:B$418,A28) -> 21 | G28: Westside size-guide popup on a women's product page (INDIA row, body measurements in cm; screenshot supplied by the user). Replaces numbers stored earlier from a different Westside page, which were bust +1, waist +3 (XS and up), hip +2 higher and had no XXL. Which page is current is not known; this popup is what a shopper sees at the size selector.
... A43: Zudio | B43: XS–3XL | C43: Placeholder | D43: Men | E43: chest, waist, hip | F43: =COUNTIFS('All measurements'!A$5:A$418,D43,'All measurements'!B$5:B$418,A43) -> 21 | G43: PLACEHOLDER — no men's chart sourced for this brand (Zudio's site was down; a Google AI summary was found but not used, because its numbers can't be traced to Zudio and contradict themselves). Numbers are, per measurement, the average of every real men's chart in this file that publishes it at every size XS-3XL: chest Adidas, H&M, Levi's, Marks & Spencer, Nike, The Souled Store, Westside; waist Adidas, H&M, Levi's, Nike, Westside; hip Adidas, Levi's, Nike, Westside. Replace with the brand's own chart when sourced.
A45: Removed in v8: Roadster and HRX (no real chart; not kept as invented numbers).

Sheet All measurements
A1: Every stored measurement, with the published value it came from
A2: Blue = transcribed from a size-guide screenshot. Black = formula. 'Recorded earlier' = stored in a previous version; the raw published values weren't re-transcribed for this sheet, so the stored value is entered directly.
A4: Gender | B4: Brand | C4: Size | D4: Measurement | E4: Published low | F4: Published high | G4: Published single value | H4: Published unit | I4: How stored | J4: Stored value (cm) | K4: Status
A5: Women | B5: Adidas | C5: XXS | D5: bust | H5: cm | I5: recorded earlier | J5: 74.5 | K5: Sourced
A6: Women | B6: Adidas | C6: XXS | D6: waist | H6: cm | I6: recorded earlier | J6: 58.5 | K6: Sourced
A7: Women | B7: Adidas | C7: XXS | D7: hip | H7: cm | I7: recorded earlier | J7: 83.5 | K7: Sourced
A8: Women | B8: Adidas | C8: XS | D8: bust | H8: cm | I8: recorded earlier | J8: 79.5 | K8: Sourced
A9: Women | B9: Adidas | C9: XS | D9: waist | H9: cm | I9: recorded earlier | J9: 63.5 | K9: Sourced
A10: Women | B10: Adidas | C10: XS | D10: hip | H10: cm | I10: recorded earlier | J10: 88.5 | K10: Sourced
A11: Women | B11: Adidas | C11: S | D11: bust | H11: cm | I11: recorded earlier | J11: 85.5 | K11: Sourced
A12: Women | B12: Adidas | C12: S | D12: waist | H12: cm | I12: recorded earlier | J12: 69.5 | K12: Sourced
A13: Women | B13: Adidas | C13: S | D13: hip | H13: cm | I13: recorded earlier | J13: 94.5 | K13: Sourced
A14: Women | B14: Adidas | C14: M | D14: bust | H14: cm | I14: recorded earlier | J14: 91.5 | K14: Sourced
A15: Women | B15: Adidas | C15: M | D15: waist | H15: cm | I15: recorded earlier | J15: 75.5 | K15: Sourced
A16: Women | B16: Adidas | C16: M | D16: hip | H16: cm | I16: recorded earlier | J16: 100.5 | K16: Sourced
... A31: Women | B31: Adidas | C31: 4XL | D31: hip | H31: cm | I31: recorded earlier | J31: 145.5 | K31: Sourced
A32: Women | B32: H&M | C32: XXS | D32: bust | E32: 74 | F32: 78 | H32: cm | I32: midpoint of range | J32: =(E32+F32)/2 -> 76 | K32: Sourced
A33: Women | B33: H&M | C33: XXS | D33: waist | E33: 62 | F33: 64 | H33: cm | I33: midpoint of range | J33: =(E33+F33)/2 -> 63 | K33: Sourced
A34: Women | B34: H&M | C34: XXS | D34: hip | E34: 79 | F34: 83 | H34: cm | I34: midpoint of range | J34: =(E34+F34)/2 -> 81 | K34: Sourced
A35: Women | B35: H&M | C35: XS | D35: bust | E35: 78 | F35: 82 | H35: cm | I35: midpoint of range | J35: =(E35+F35)/2 -> 80 | K35: Sourced
A36: Women | B36: H&M | C36: XS | D36: waist | E36: 64 | F36: 66 | H36: cm | I36: midpoint of range | J36: =(E36+F36)/2 -> 65 | K36: Sourced
A37: Women | B37: H&M | C37: XS | D37: hip | E37: 83 | F37: 87 | H37: cm | I37: midpoint of range | J37: =(E37+F37)/2 -> 85 | K37: Sourced
A38: Women | B38: H&M | C38: S | D38: bust | E38: 82 | F38: 90 | H38: cm | I38: midpoint of range | J38: =(E38+F38)/2 -> 86 | K38: Sourced
A39: Women | B39: H&M | C39: S | D39: waist | E39: 66 | F39: 74 | H39: cm | I39: midpoint of range | J39: =(E39+F39)/2 -> 70 | K39: Sourced
A40: Women | B40: H&M | C40: S | D40: hip | E40: 87 | F40: 94.5 | H40: cm | I40: midpoint of range | J40: =(E40+F40)/2 -> 90.75 | K40: Sourced
A41: Women | B41: H&M | C41: M | D41: bust | E41: 90 | F41: 98 | H41: cm | I41: midpoint of range | J41: =(E41+F41)/2 -> 94 | K41: Sourced
A42: Women | B42: H&M | C42: M | D42: waist | E42: 74 | F42: 82.5 | H42: cm | I42: midpoint of range | J42: =(E42+F42)/2 -> 78.25 | K42: Sourced
A43: Women | B43: H&M | C43: M | D43: hip | E43: 94.5 | F43: 100.5 | H43: cm | I43: midpoint of range | J43: =(E43+F43)/2 -> 97.5 | K43: Sourced
... A58: Women | B58: H&M | C58: 4XL | D58: hip | E58: 140 | F58: 152 | H58: cm | I58: midpoint of range | J58: =(E58+F58)/2 -> 146 | K58: Sourced
A59: Women | B59: Levi's | C59: XXS | D59: bust | H59: cm | I59: recorded earlier | J59: 78.7 | K59: Sourced
A60: Women | B60: Levi's | C60: XXS | D60: waist | H60: cm | I60: recorded earlier | J60: 61.6 | K60: Sourced
A61: Women | B61: Levi's | C61: XXS | D61: hip | H61: cm | I61: recorded earlier | J61: 86.4 | K61: Sourced
A62: Women | B62: Levi's | C62: XS | D62: bust | H62: cm | I62: recorded earlier | J62: 83.8 | K62: Sourced
A63: Women | B63: Levi's | C63: XS | D63: waist | H63: cm | I63: recorded earlier | J63: 66.7 | K63: Sourced
A64: Women | B64: Levi's | C64: XS | D64: hip | H64: cm | I64: recorded earlier | J64: 91.4 | K64: Sourced
A65: Women | B65: Levi's | C65: S | D65: bust | H65: cm | I65: recorded earlier | J65: 88.9 | K65: Sourced
A66: Women | B66: Levi's | C66: S | D66: waist | H66: cm | I66: recorded earlier | J66: 71.8 | K66: Sourced
A67: Women | B67: Levi's | C67: S | D67: hip | H67: cm | I67: recorded earlier | J67: 96.5 | K67: Sourced
A68: Women | B68: Levi's | C68: M | D68: bust | H68: cm | I68: recorded earlier | J68: 94 | K68: Sourced
A69: Women | B69: Levi's | C69: M | D69: waist | H69: cm | I69: recorded earlier | J69: 76.8 | K69: Sourced
...

Sheet Women bust grid
A1: Women's bust (cm) by brand and size — read side by side
A2: Pulled from 'All measurements' by formula. Blank = that brand doesn't make the size.
A4: Brand | B4: Status | C4: XXS | D4: XS | E4: S | F4: M | G4: L | H4: XL | I4: XXL | J4: 3XL | K4: 4XL
A5: Adidas | B5: Sourced | C5: =IF(COUNTIFS('All measurements'!$A$5:$A$418,"Women",'All measurements'!$B$5:$B$418,$A5,'All measurements'!$C$5:$C$418,C$4,'All measurements'!$D$5:$D$418,"bust")=0,"",SUMIFS('All measurements'!$J$5:$J$418,'All measurements'!$A$5:$A$418,"Women",'All measurements'!$B$5:$B$418,$A5,'All measurements'!$C$5:$C$418,C$4,'All measurements'!$D$5:$D$418,"bust")) -> 74.5 | D5: =IF(COUNTIFS('All measurements'!$A$5:$A$418,"Women",'All measurements'!$B$5:$B$418,$A5,'All measurements'!$C$5:$C$418,D$4,'All measurements'!$D$5:$D$418,"bust")=0,"",SUMIFS('All measurements'!$J$5:$J$418,'All measurements'!$A$5:$A$418,"Women",'All measurements'!$B$5:$B$418,$A5,'All measurements'!$C$5:$C$418,D$4,'All measurements'!$D$5:$D$418,"bust")) -> 79.5 | E5: =IF(COUNTIFS('All measurements'!$A$5:$A$418,"Women",'All measurements'!$B$5:$B$418,$A5,'All measurements'!$C$5:$C$418,E$4,'All measurements'!$D$5:$D$418,"bust")=0,"",SUMIFS('All measurements'!$J$5:$J$418,'All measurements'!$A$5:$A$418,"Women",'All measurements'!$B$5:$B$418,$A5,'All measurements'!$C$5:$C$418,E$4,'All measurements'!$D$5:$D$418,"bust")) -> 85.5 | F5: =IF(COUNTIFS('All measurements'!$A$5:$A$418,"Women",'All measurements'!$B$5:$B$418,$A5,'All measurements'!$C$5:$C$418,F$4,'All measurements'!$D$5:$D$418,"bust")=0,"",SUMIFS('All measurements'!$J$5:$J$418,'All measurements'!$A$5:$A$418,"Women",'All measurements'!$B$5:$B$418,$A5,'All measurements'!$C$5:$C$418,F$4,'All measurements'!$D$5:$D$418,"bust")) -> 91.5 | G5: =IF(COUNTIFS('All measurements'!$A$5:$A$418,"Women",'All measurements'!$B$5:$B$418,$A5,'All measurements'!$C$5:$C$418,G$4,'All measurements'!$D$5:$D$418,"bust")=0,"",SUMIFS('All measurements'!$J$5:$J$418,'All measurements'!$A$5:$A$418,"Women",'All measurements'!$B$5:$B$418,$A5,'All measurements'!$C$5:$C$418,G$4,'All measurements'!$D$5:$D$418,"bust")) -> 98 | H5: =IF(COUNTIFS('All measurements'!$A$5:$A$418,"Women",'All measurements'!$B$5:$B$418,$A5,'All measurements'!$C$5:$C$418,H$4,'All measurements'!$D$5:$D$418,"bust")=0,"",SUMIFS('All measurements'!$J$5:$J$418,'All measurements'!$A$5:$A$418,"Women",'All measurements'!$B$5:$B$418,$A5,'All measurements'!$C$5:$C$418,H$4,'All measurements'!$D$5:$D$418,"bust")) -> 105.5 | I5: =IF(COUNTIFS('All measurements'!$A$5:$A$418,"Women",'All measurements'!$B$5:$B$418,$A5,'All measurements'!$C$5:$C$418,I$4,'All measurements'!$D$5:$D$418,"bust")=0,"",SUMIFS('All measurements'!$J$5:$J$418,'All measurements'!$A$5:$A$418,"Women",'All measurements'!$B$5:$B$418,$A5,'All measurements'!$C$5:$C$418,I$4,'All measurements'!$D$5:$D$418,"bust")) -> 114 | J5: =IF(COUNTIFS('All measurements'!$A$5:$A$418,"Women",'All measurements'!$B$5:$B$418,$A5,'All measurements'!$C$5:$C$418,J$4,'All measurements'!$D$5:$D$418,"bust")=0,"",SUMIFS('All measurements'!$J$5:$J$418,'All measurements'!$A$5:$A$418,"Women",'All measurements'!$B$5:$B$418,$A5,'All measurements'!$C$5:$C$418,J$4,'All measurements'!$D$5:$D$418,"bust")) -> 128.5 | K5: =IF(COUNTIFS('All measurements'!$A$5:$A$418,"Women",'All measurements'!$B$5:$B$418,$A5,'All measurements'!$C$5:$C$418,K$4,'All measurements'!$D$5:$D$418,"bust")=0,"",SUMIFS('All measurements'!$J$5:$J$418,'All measurements'!$A$5:$A$418,"Women",'All measurements'!$B$5:$B$418,$A5,'All measurements'!$C$5:$C$418,K$4,'All measurements'!$D$5:$D$418,"bust")) -> 138.5
A6: H&M | B6: Sourced | C6: =IF(COUNTIFS('All measurements'!$A$5:$A$418,"Women",'All measurements'!$B$5:$B$418,$A6,'All measurements'!$C$5:$C$418,C$4,'All measurements'!$D$5:$D$418,"bust")=0,"",SUMIFS('All measurements'!$J$5:$J$418,'All measurements'!$A$5:$A$418,"Women",'All measurements'!$B$5:$B$418,$A6,'All measurements'!$C$5:$C$418,C$4,'All measurements'!$D$5:$D$418,"bust")) -> 76 | D6: =IF(COUNTIFS('All measurements'!$A$5:$A$418,"Women",'All measurements'!$B$5:$B$418,$A6,'All measurements'!$C$5:$C$418,D$4,'All measurements'!$D$5:$D$418,"bust")=0,"",SUMIFS('All measurements'!$J$5:$J$418,'All measurements'!$A$5:$A$418,"Women",'All measurements'!$B$5:$B$418,$A6,'All measurements'!$C$5:$C$418,D$4,'All measurements'!$D$5:$D$418,"bust")) -> 80 | E6: =IF(COUNTIFS('All measurements'!$A$5:$A$418,"Women",'All measurements'!$B$5:$B$418,$A6,'All measurements'!$C$5:$C$418,E$4,'All measurements'!$D$5:$D$418,"bust")=0,"",SUMIFS('All measurements'!$J$5:$J$418,'All measurements'!$A$5:$A$418,"Women",'All measurements'!$B$5:$B$418,$A6,'All measurements'!$C$5:$C$418,E$4,'All measurements'!$D$5:$D$418,"bust")) -> 86 | F6: =IF(COUNTIFS('All measurements'!$A$5:$A$418,"Women",'All measurements'!$B$5:$B$418,$A6,'All measurements'!$C$5:$C$418,F$4,'All measurements'!$D$5:$D$418,"bust")=0,"",SUMIFS('All measurements'!$J$5:$J$418,'All measurements'!$A$5:$A$418,"Women",'All measurements'!$B$5:$B$418,$A6,'All measurements'!$C$5:$C$418,F$4,'All measurements'!$D$5:$D$418,"bust")) -> 94 | G6: =IF(COUNTIFS('All measurements'!$A$5:$A$418,"Women",'All measurements'!$B$5:$B$418,$A6,'All measurements'!$C$5:$C$418,G$4,'All measurements'!$D$5:$D$418,"bust")=0,"",SUMIFS('All measurements'!$J$5:$J$418,'All measurements'!$A$5:$A$418,"Women",'All measurements'!$B$5:$B$418,$A6,'All measurements'!$C$5:$C$418,G$4,'All measurements'!$D$5:$D$418,"bust")) -> 102.5 | H6: =IF(COUNTIFS('All measurements'!$A$5:$A$418,"Women",'All measurements'!$B$5:$B$418,$A6,'All measurements'!$C$5:$C$418,H$4,'All measurements'!$D$5:$D$418,"bust")=0,"",SUMIFS('All measurements'!$J$5:$J$418,'All measurements'!$A$5:$A$418,"Women",'All measurements'!$B$5:$B$418,$A6,'All measurements'!$C$5:$C$418,H$4,'All measurements'!$D$5:$D$418,"bust")) -> 113 | I6: =IF(COUNTIFS('All measurements'!$A$5:$A$418,"Women",'All measurements'!$B$5:$B$418,$A6,'All measurements'!$C$5:$C$418,I$4,'All measurements'!$D$5:$D$418,"bust")=0,"",SUMIFS('All measurements'!$J$5:$J$418,'All measurements'!$A$5:$A$418,"Women",'All measurements'!$B$5:$B$418,$A6,'All measurements'!$C$5:$C$418,I$4,'All measurements'!$D$5:$D$418,"bust")) -> 125 | J6: =IF(COUNTIFS('All measurements'!$A$5:$A$418,"Women",'All measurements'!$B$5:$B$418,$A6,'All measurements'!$C$5:$C$418,J$4,'All measurements'!$D$5:$D$418,"bust")=0,"",SUMIFS('All measurements'!$J$5:$J$418,'All measurements'!$A$5:$A$418,"Women",'All measurements'!$B$5:$B$418,$A6,'All measurements'!$C$5:$C$418,J$4,'All measurements'!$D$5:$D$418,"bust")) -> 137 | K6: =IF(COUNTIFS('All measurements'!$A$5:$A$418,"Women",'All measurements'!$B$5:$B$418,$A6,'All measurements'!$C$5:$C$418,K$4,'All measurements'!$D$5:$D$418,"bust")=0,"",SUMIFS('All measurements'!$J$5:$J$418,'All measurements'!$A$5:$A$418,"Women",'All measurements'!$B$5:$B$418,$A6,'All measurements'!$C$5:$C$418,K$4,'All measurements'!$D$5:$D$418,"bust")) -> 149
A7: Levi's | B7: Sourced | C7: =IF(COUNTIFS('All measurements'!$A$5:$A$418,"Women",'All measurements'!$B$5:$B$418,$A7,'All measurements'!$C$5:$C$418,C$4,'All measurements'!$D$5:$D$418,"bust")=0,"",SUMIFS('All measurements'!$J$5:$J$418,'All measurements'!$A$5:$A$418,"Women",'All measurements'!$B$5:$B$418,$A7,'All measurements'!$C$5:$C$418,C$4,'All measurements'!$D$5:$D$418,"bust")) -> 78.7 | D7: =IF(COUNTIFS('All measurements'!$A$5:$A$418,"Women",'All measurements'!$B$5:$B$418,$A7,'All measurements'!$C$5:$C$418,D$4,'All measurements'!$D$5:$D$418,"bust")=0,"",SUMIFS('All measurements'!$J$5:$J$418,'All measurements'!$A$5:$A$418,"Women",'All measurements'!$B$5:$B$418,$A7,'All measurements'!$C$5:$C$418,D$4,'All measurements'!$D$5:$D$418,"bust")) -> 83.8 | E7: =IF(COUNTIFS('All measurements'!$A$5:$A$418,"Women",'All measurements'!$B$5:$B$418,$A7,'All measurements'!$C$5:$C$418,E$4,'All measurements'!$D$5:$D$418,"bust")=0,"",SUMIFS('All measurements'!$J$5:$J$418,'All measurements'!$A$5:$A$418,"Women",'All measurements'!$B$5:$B$418,$A7,'All measurements'!$C$5:$C$418,E$4,'All measurements'!$D$5:$D$418,"bust")) -> 88.9 | F7: =IF(COUNTIFS('All measurements'!$A$5:$A$418,"Women",'All measurements'!$B$5:$B$418,$A7,'All measurements'!$C$5:$C$418,F$4,'All measurements'!$D$5:$D$418,"bust")=0,"",SUMIFS('All measurements'!$J$5:$J$418,'All measurements'!$A$5:$A$418,"Women",'All measurements'!$B$5:$B$418,$A7,'All measurements'!$C$5:$C$418,F$4,'All measurements'!$D$5:$D$418,"bust")) -> 94 | G7: =IF(COUNTIFS('All measurements'!$A$5:$A$418,"Women",'All measurements'!$B$5:$B$418,$A7,'All measurements'!$C$5:$C$418,G$4,'All measurements'!$D$5:$D$418,"bust")=0,"",SUMIFS('All measurements'!$J$5:$J$418,'All measurements'!$A$5:$A$418,"Women",'All measurements'!$B$5:$B$418,$A7,'All measurements'!$C$5:$C$418,G$4,'All measurements'!$D$5:$D$418,"bust")) -> 100.3 | H7: =IF(COUNTIFS('All measurements'!$A$5:$A$418,"Women",'All measurements'!$B$5:$B$418,$A7,'All measurements'!$C$5:$C$418,H$4,'All measurements'!$D$5:$D$418,"bust")=0,"",SUMIFS('All measurements'!$J$5:$J$418,'All measurements'!$A$5:$A$418,"Women",'All measurements'!$B$5:$B$418,$A7,'All measurements'!$C$5:$C$418,H$4,'All measurements'!$D$5:$D$418,"bust")) -> 108 | I7: =IF(COUNTIFS('All measurements'!$A$5:$A$418,"Women",'All measurements'!$B$5:$B$418,$A7,'All measurements'!$C$5:$C$418,I$4,'All measurements'!$D$5:$D$418,"bust")=0,"",SUMIFS('All measurements'!$J$5:$J$418,'All measurements'!$A$5:$A$418,"Women",'All measurements'!$B$5:$B$418,$A7,'All measurements'!$C$5:$C$418,I$4,'All measurements'!$D$5:$D$418,"bust")) -> 115.6 | J7: =IF(COUNTIFS('All measurements'!$A$5:$A$418,"Women",'All measurements'!$B$5:$B$418,$A7,'All measurements'!$C$5:$C$418,J$4,'All measurements'!$D$5:$D$418,"bust")=0,"",SUMIFS('All measurements'!$J$5:$J$418,'All measurements'!$A$5:$A$418,"Women",'All measurements'!$B$5:$B$418,$A7,'All measurements'!$C$5:$C$418,J$4,'All measurements'!$D$5:$D$418,"bust")) -> 130.8 | K7: =IF(COUNTIFS('All measurements'!$A$5:$A$418,"Women",'All measurements'!$B$5:$B$418,$A7,'All measurements'!$C$5:$C$418,K$4,'All measurements'!$D$5:$D$418,"bust")=0,"",SUMIFS('All measurements'!$J$5:$J$418,'All measurements'!$A$5:$A$418,"Women",'All measurements'!$B$5:$B$418,$A7,'All measurements'!$C$5:$C$418,K$4,'All measurements'!$D$5:$D$418,"bust"))
A8: Lulu & Sky | B8: Sourced | C8: =IF(COUNTIFS('All measurements'!$A$5:$A$418,"Women",'All measurements'!$B$5:$B$418,$A8,'All measurements'!$C$5:$C$418,C$4,'All measurements'!$D$5:$D$418,"bust")=0,"",SUMIFS('All measurements'!$J$5:$J$418,'All measurements'!$A$5:$A$418,"Women",'All measurements'!$B$5:$B$418,$A8,'All measurements'!$C$5:$C$418,C$4,'All measurements'!$D$5:$D$418,"bust")) | D8: =IF(COUNTIFS('All measurements'!$A$5:$A$418,"Women",'All measurements'!$B$5:$B$418,$A8,'All measurements'!$C$5:$C$418,D$4,'All measurements'!$D$5:$D$418,"bust")=0,"",SUMIFS('All measurements'!$J$5:$J$418,'All measurements'!$A$5:$A$418,"Women",'All measurements'!$B$5:$B$418,$A8,'All measurements'!$C$5:$C$418,D$4,'All measurements'!$D$5:$D$418,"bust")) | E8: =IF(COUNTIFS('All measurements'!$A$5:$A$418,"Women",'All measurements'!$B$5:$B$418,$A8,'All measurements'!$C$5:$C$418,E$4,'All measurements'!$D$5:$D$418,"bust")=0,"",SUMIFS('All measurements'!$J$5:$J$418,'All measurements'!$A$5:$A$418,"Women",'All measurements'!$B$5:$B$418,$A8,'All measurements'!$C$5:$C$418,E$4,'All measurements'!$D$5:$D$418,"bust")) -> 78.74 | F8: =IF(COUNTIFS('All measurements'!$A$5:$A$418,"Women",'All measurements'!$B$5:$B$418,$A8,'All measurements'!$C$5:$C$418,F$4,'All measurements'!$D$5:$D$418,"bust")=0,"",SUMIFS('All measurements'!$J$5:$J$418,'All measurements'!$A$5:$A$418,"Women",'All measurements'!$B$5:$B$418,$A8,'All measurements'!$C$5:$C$418,F$4,'All measurements'!$D$5:$D$418,"bust")) -> 81.28 | G8: =IF(COUNTIFS('All measurements'!$A$5:$A$418,"Women",'All measurements'!$B$5:$B$418,$A8,'All measurements'!$C$5:$C$418,G$4,'All measurements'!$D$5:$D$418,"bust")=0,"",SUMIFS('All measurements'!$J$5:$J$418,'All measurements'!$A$5:$A$418,"Women",'All measurements'!$B$5:$B$418,$A8,'All measurements'!$C$5:$C$418,G$4,'All measurements'!$D$5:$D$418,"bust")) -> 88.9 | H8: =IF(COUNTIFS('All measurements'!$A$5:$A$418,"Women",'All measurements'!$B$5:$B$418,$A8,'All measurements'!$C$5:$C$418,H$4,'All measurements'!$D$5:$D$418,"bust")=0,"",SUMIFS('All measurements'!$J$5:$J$418,'All measurements'!$A$5:$A$418,"Women",'All measurements'!$B$5:$B$418,$A8,'All measurements'!$C$5:$C$418,H$4,'All measurements'!$D$5:$D$418,"bust")) -> 93.98 | I8: =IF(COUNTIFS('All measurements'!$A$5:$A$418,"Women",'All measurements'!$B$5:$B$418,$A8,'All measurements'!$C$5:$C$418,I$4,'All measurements'!$D$5:$D$418,"bust")=0,"",SUMIFS('All measurements'!$J$5:$J$418,'All measurements'!$A$5:$A$418,"Women",'All measurements'!$B$5:$B$418,$A8,'All measurements'!$C$5:$C$418,I$4,'All measurements'!$D$5:$D$418,"bust")) | J8: =IF(COUNTIFS('All measurements'!$A$5:$A$418,"Women",'All measurements'!$B$5:$B$418,$A8,'All measurements'!$C$5:$C$418,J$4,'All measurements'!$D$5:$D$418,"bust")=0,"",SUMIFS('All measurements'!$J$5:$J$418,'All measurements'!$A$5:$A$418,"Women",'All measurements'!$B$5:$B$418,$A8,'All measurements'!$C$5:$C$418,J$4,'All measurements'!$D$5:$D$418,"bust")) | K8: =IF(COUNTIFS('All measurements'!$A$5:$A$418,"Women",'All measurements'!$B$5:$B$418,$A8,'All measurements'!$C$5:$C$418,K$4,'All measurements'!$D$5:$D$418,"bust")=0,"",SUMIFS('All measurements'!$J$5:$J$418,'All measurements'!$A$5:$A$418,"Women",'All measurements'!$B$5:$B$418,$A8,'All measurements'!$C$5:$C$418,K$4,'All measurements'!$D$5:$D$418,"bust"))
A9: Marks & Spencer | B9: Sourced | C9: =IF(COUNTIFS('All measurements'!$A$5:$A$418,"Women",'All measurements'!$B$5:$B$418,$A9,'All measurements'!$C$5:$C$418,C$4,'All measurements'!$D$5:$D$418,"bust")=0,"",SUMIFS('All measurements'!$J$5:$J$418,'All measurements'!$A$5:$A$418,"Women",'All measurements'!$B$5:$B$418,$A9,'All measurements'!$C$5:$C$418,C$4,'All measurements'!$D$5:$D$418,"bust")) | D9: =IF(COUNTIFS('All measurements'!$A$5:$A$418,"Women",'All measurements'!$B$5:$B$418,$A9,'All measurements'!$C$5:$C$418,D$4,'All measurements'!$D$5:$D$418,"bust")=0,"",SUMIFS('All measurements'!$J$5:$J$418,'All measurements'!$A$5:$A$418,"Women",'All measurements'!$B$5:$B$418,$A9,'All measurements'!$C$5:$C$418,D$4,'All measurements'!$D$5:$D$418,"bust")) -> 78 | E9: =IF(COUNTIFS('All measurements'!$A$5:$A$418,"Women",'All measurements'!$B$5:$B$418,$A9,'All measurements'!$C$5:$C$418,E$4,'All measurements'!$D$5:$D$418,"bust")=0,"",SUMIFS('All measurements'!$J$5:$J$418,'All measurements'!$A$5:$A$418,"Women",'All measurements'!$B$5:$B$418,$A9,'All measurements'!$C$5:$C$418,E$4,'All measurements'!$D$5:$D$418,"bust")) -> 84.5 | F9: =IF(COUNTIFS('All measurements'!$A$5:$A$418,"Women",'All measurements'!$B$5:$B$418,$A9,'All measurements'!$C$5:$C$418,F$4,'All measurements'!$D$5:$D$418,"bust")=0,"",SUMIFS('All measurements'!$J$5:$J$418,'All measurements'!$A$5:$A$418,"Women",'All measurements'!$B$5:$B$418,$A9,'All measurements'!$C$5:$C$418,F$4,'All measurements'!$D$5:$D$418,"bust")) -> 94.5 | G9: =IF(COUNTIFS('All measurements'!$A$5:$A$418,"Women",'All measurements'!$B$5:$B$418,$A9,'All measurements'!$C$5:$C$418,G$4,'All measurements'!$D$5:$D$418,"bust")=0,"",SUMIFS('All measurements'!$J$5:$J$418,'All measurements'!$A$5:$A$418,"Women",'All measurements'!$B$5:$B$418,$A9,'All measurements'!$C$5:$C$418,G$4,'All measurements'!$D$5:$D$418,"bust")) -> 105.25 | H9: =IF(COUNTIFS('All measurements'!$A$5:$A$418,"Women",'All measurements'!$B$5:$B$418,$A9,'All measurements'!$C$5:$C$418,H$4,'All measurements'!$D$5:$D$418,"bust")=0,"",SUMIFS('All measurements'!$J$5:$J$418,'All measurements'!$A$5:$A$418,"Women",'All measurements'!$B$5:$B$418,$A9,'All measurements'!$C$5:$C$418,H$4,'All measurements'!$D$5:$D$418,"bust")) -> 117 | I9: =IF(COUNTIFS('All measurements'!$A$5:$A$418,"Women",'All measurements'!$B$5:$B$418,$A9,'All measurements'!$C$5:$C$418,I$4,'All measurements'!$D$5:$D$418,"bust")=0,"",SUMIFS('All measurements'!$J$5:$J$418,'All measurements'!$A$5:$A$418,"Women",'All measurements'!$B$5:$B$418,$A9,'All measurements'!$C$5:$C$418,I$4,'All measurements'!$D$5:$D$418,"bust")) -> 129 | J9: =IF(COUNTIFS('All measurements'!$A$5:$A$418,"Women",'All measurements'!$B$5:$B$418,$A9,'All measurements'!$C$5:$C$418,J$4,'All measurements'!$D$5:$D$418,"bust")=0,"",SUMIFS('All measurements'!$J$5:$J$418,'All measurements'!$A$5:$A$418,"Women",'All measurements'!$B$5:$B$418,$A9,'All measurements'!$C$5:$C$418,J$4,'All measurements'!$D$5:$D$418,"bust")) | K9: =IF(COUNTIFS('All measurements'!$A$5:$A$418,"Women",'All measurements'!$B$5:$B$418,$A9,'All measurements'!$C$5:$C$418,K$4,'All measurements'!$D$5:$D$418,"bust")=0,"",SUMIFS('All measurements'!$J$5:$J$418,'All measurements'!$A$5:$A$418,"Women",'All measurements'!$B$5:$B$418,$A9,'All measurements'!$C$5:$C$418,K$4,'All measurements'!$D$5:$D$418,"bust"))
A10: Max | B10: Sourced | C10: =IF(COUNTIFS('All measurements'!$A$5:$A$418,"Women",'All measurements'!$B$5:$B$418,$A10,'All measurements'!$C$5:$C$418,C$4,'All measurements'!$D$5:$D$418,"bust")=0,"",SUMIFS('All measurements'!$J$5:$J$418,'All measurements'!$A$5:$A$418,"Women",'All measurements'!$B$5:$B$418,$A10,'All measurements'!$C$5:$C$418,C$4,'All measurements'!$D$5:$D$418,"bust")) | D10: =IF(COUNTIFS('All measurements'!$A$5:$A$418,"Women",'All measurements'!$B$5:$B$418,$A10,'All measurements'!$C$5:$C$418,D$4,'All measurements'!$D$5:$D$418,"bust")=0,"",SUMIFS('All measurements'!$J$5:$J$418,'All measurements'!$A$5:$A$418,"Women",'All measurements'!$B$5:$B$418,$A10,'All measurements'!$C$5:$C$418,D$4,'All measurements'!$D$5:$D$418,"bust")) -> 81.3 | E10: =IF(COUNTIFS('All measurements'!$A$5:$A$418,"Women",'All measurements'!$B$5:$B$418,$A10,'All measurements'!$C$5:$C$418,E$4,'All measurements'!$D$5:$D$418,"bust")=0,"",SUMIFS('All measurements'!$J$5:$J$418,'All measurements'!$A$5:$A$418,"Women",'All measurements'!$B$5:$B$418,$A10,'All measurements'!$C$5:$C$418,E$4,'All measurements'!$D$5:$D$418,"bust")) -> 86.4 | F10: =IF(COUNTIFS('All measurements'!$A$5:$A$418,"Women",'All measurements'!$B$5:$B$418,$A10,'All measurements'!$C$5:$C$418,F$4,'All measurements'!$D$5:$D$418,"bust")=0,"",SUMIFS('All measurements'!$J$5:$J$418,'All measurements'!$A$5:$A$418,"Women",'All measurements'!$B$5:$B$418,$A10,'All measurements'!$C$5:$C$418,F$4,'All measurements'!$D$5:$D$418,"bust")) -> 91.4 | G10: =IF(COUNTIFS('All measurements'!$A$5:$A$418,"Women",'All measurements'!$B$5:$B$418,$A10,'All measurements'!$C$5:$C$418,G$4,'All measurements'!$D$5:$D$418,"bust")=0,"",SUMIFS('All measurements'!$J$5:$J$418,'All measurements'!$A$5:$A$418,"Women",'All measurements'!$B$5:$B$418,$A10,'All measurements'!$C$5:$C$418,G$4,'All measurements'!$D$5:$D$418,"bust")) -> 96.5 | H10: =IF(COUNTIFS('All measurements'!$A$5:$A$418,"Women",'All measurements'!$B$5:$B$418,$A10,'All measurements'!$C$5:$C$418,H$4,'All measurements'!$D$5:$D$418,"bust")=0,"",SUMIFS('All measurements'!$J$5:$J$418,'All measurements'!$A$5:$A$418,"Women",'All measurements'!$B$5:$B$418,$A10,'All measurements'!$C$5:$C$418,H$4,'All measurements'!$D$5:$D$418,"bust")) -> 102 | I10: =IF(COUNTIFS('All measurements'!$A$5:$A$418,"Women",'All measurements'!$B$5:$B$418,$A10,'All measurements'!$C$5:$C$418,I$4,'All measurements'!$D$5:$D$418,"bust")=0,"",SUMIFS('All measurements'!$J$5:$J$418,'All measurements'!$A$5:$A$418,"Women",'All measurements'!$B$5:$B$418,$A10,'All measurements'!$C$5:$C$418,I$4,'All measurements'!$D$5:$D$418,"bust")) -> 107 | J10: =IF(COUNTIFS('All measurements'!$A$5:$A$418,"Women",'All measurements'!$B$5:$B$418,$A10,'All measurements'!$C$5:$C$418,J$4,'All measurements'!$D$5:$D$418,"bust")=0,"",SUMIFS('All measurements'!$J$5:$J$418,'All measurements'!$A$5:$A$418,"Women",'All measurements'!$B$5:$B$418,$A10,'All measurements'!$C$5:$C$418,J$4,'All measurements'!$D$5:$D$418,"bust")) -> 115 | K10: =IF(COUNTIFS('All measurements'!$A$5:$A$418,"Women",'All measurements'!$B$5:$B$418,$A10,'All measurements'!$C$5:$C$418,K$4,'All measurements'!$D$5:$D$418,"bust")=0,"",SUMIFS('All measurements'!$J$5:$J$418,'All measurements'!$A$5:$A$418,"Women",'All measurements'!$B$5:$B$418,$A10,'All measurements'!$C$5:$C$418,K$4,'All measurements'!$D$5:$D$418,"bust")) -> 121
A11: Nike | B11: Sourced | C11: =IF(COUNTIFS('All measurements'!$A$5:$A$418,"Women",'All measurements'!$B$5:$B$418,$A11,'All measurements'!$C$5:$C$418,C$4,'All measurements'!$D$5:$D$418,"bust")=0,"",SUMIFS('All measurements'!$J$5:$J$418,'All measurements'!$A$5:$A$418,"Women",'All measurements'!$B$5:$B$418,$A11,'All measurements'!$C$5:$C$418,C$4,'All measurements'!$D$5:$D$418,"bust")) | D11: =IF(COUNTIFS('All measurements'!$A$5:$A$418,"Women",'All measurements'!$B$5:$B$418,$A11,'All measurements'!$C$5:$C$418,D$4,'All measurements'!$D$5:$D$418,"bust")=0,"",SUMIFS('All measurements'!$J$5:$J$418,'All measurements'!$A$5:$A$418,"Women",'All measurements'!$B$5:$B$418,$A11,'All measurements'!$C$5:$C$418,D$4,'All measurements'!$D$5:$D$418,"bust")) -> 78.75 | E11: =IF(COUNTIFS('All measurements'!$A$5:$A$418,"Women",'All measurements'!$B$5:$B$418,$A11,'All measurements'!$C$5:$C$418,E$4,'All measurements'!$D$5:$D$418,"bust")=0,"",SUMIFS('All measurements'!$J$5:$J$418,'All measurements'!$A$5:$A$418,"Women",'All measurements'!$B$5:$B$418,$A11,'All measurements'!$C$5:$C$418,E$4,'All measurements'!$D$5:$D$418,"bust")) -> 83.2 | F11: =IF(COUNTIFS('All measurements'!$A$5:$A$418,"Women",'All measurements'!$B$5:$B$418,$A11,'All measurements'!$C$5:$C$418,F$4,'All measurements'!$D$5:$D$418,"bust")=0,"",SUMIFS('All measurements'!$J$5:$J$418,'All measurements'!$A$5:$A$418,"Women",'All measurements'!$B$5:$B$418,$A11,'All measurements'!$C$5:$C$418,F$4,'All measurements'!$D$5:$D$418,"bust")) -> 87 | G11: =IF(COUNTIFS('All measurements'!$A$5:$A$418,"Women",'All measurements'!$B$5:$B$418,$A11,'All measurements'!$C$5:$C$418,G$4,'All measurements'!$D$5:$D$418,"bust")=0,"",SUMIFS('All measurements'!$J$5:$J$418,'All measurements'!$A$5:$A$418,"Women",'All measurements'!$B$5:$B$418,$A11,'All measurements'!$C$5:$C$418,G$4,'All measurements'!$D$5:$D$418,"bust")) -> 92.05 | H11: =IF(COUNTIFS('All measurements'!$A$5:$A$418,"Women",'All measurements'!$B$5:$B$418,$A11,'All measurements'!$C$5:$C$418,H$4,'All measurements'!$D$5:$D$418,"bust")=0,"",SUMIFS('All measurements'!$J$5:$J$418,'All measurements'!$A$5:$A$418,"Women",'All measurements'!$B$5:$B$418,$A11,'All measurements'!$C$5:$C$418,H$4,'All measurements'!$D$5:$D$418,"bust")) -> 98.4 | I11: =IF(COUNTIFS('All measurements'!$A$5:$A$418,"Women",'All measurements'!$B$5:$B$418,$A11,'All measurements'!$C$5:$C$418,I$4,'All measurements'!$D$5:$D$418,"bust")=0,"",SUMIFS('All measurements'!$J$5:$J$418,'All measurements'!$A$5:$A$418,"Women",'All measurements'!$B$5:$B$418,$A11,'All measurements'!$C$5:$C$418,I$4,'All measurements'!$D$5:$D$418,"bust")) -> 104.8 | J11: =IF(COUNTIFS('All measurements'!$A$5:$A$418,"Women",'All measurements'!$B$5:$B$418,$A11,'All measurements'!$C$5:$C$418,J$4,'All measurements'!$D$5:$D$418,"bust")=0,"",SUMIFS('All measurements'!$J$5:$J$418,'All measurements'!$A$5:$A$418,"Women",'All measurements'!$B$5:$B$418,$A11,'All measurements'!$C$5:$C$418,J$4,'All measurements'!$D$5:$D$418,"bust")) | K11: =IF(COUNTIFS('All measurements'!$A$5:$A$418,"Women",'All measurements'!$B$5:$B$418,$A11,'All measurements'!$C$5:$C$418,K$4,'All measurements'!$D$5:$D$418,"bust")=0,"",SUMIFS('All measurements'!$J$5:$J$418,'All measurements'!$A$5:$A$418,"Women",'All measurements'!$B$5:$B$418,$A11,'All measurements'!$C$5:$C$418,K$4,'All measurements'!$D$5:$D$418,"bust"))
A12: Pantaloons | B12: Sourced | C12: =IF(COUNTIFS('All measurements'!$A$5:$A$418,"Women",'All measurements'!$B$5:$B$418,$A12,'All measurements'!$C$5:$C$418,C$4,'All measurements'!$D$5:$D$418,"bust")=0,"",SUMIFS('All measurements'!$J$5:$J$418,'All measurements'!$A$5:$A$418,"Women",'All measurements'!$B$5:$B$418,$A12,'All measurements'!$C$5:$C$418,C$4,'All measurements'!$D$5:$D$418,"bust")) | D12: =IF(COUNTIFS('All measurements'!$A$5:$A$418,"Women",'All measurements'!$B$5:$B$418,$A12,'All measurements'!$C$5:$C$418,D$4,'All measurements'!$D$5:$D$418,"bust")=0,"",SUMIFS('All measurements'!$J$5:$J$418,'All measurements'!$A$5:$A$418,"Women",'All measurements'!$B$5:$B$418,$A12,'All measurements'!$C$5:$C$418,D$4,'All measurements'!$D$5:$D$418,"bust")) -> 83.82 | E12: =IF(COUNTIFS('All measurements'!$A$5:$A$418,"Women",'All measurements'!$B$5:$B$418,$A12,'All measurements'!$C$5:$C$418,E$4,'All measurements'!$D$5:$D$418,"bust")=0,"",SUMIFS('All measurements'!$J$5:$J$418,'All measurements'!$A$5:$A$418,"Women",'All measurements'!$B$5:$B$418,$A12,'All measurements'!$C$5:$C$418,E$4,'All measurements'!$D$5:$D$418,"bust")) -> 88.9 | F12: =IF(COUNTIFS('All measurements'!$A$5:$A$418,"Women",'All measurements'!$B$5:$B$418,$A12,'All measurements'!$C$5:$C$418,F$4,'All measurements'!$D$5:$D$418,"bust")=0,"",SUMIFS('All measurements'!$J$5:$J$418,'All measurements'!$A$5:$A$418,"Women",'All measurements'!$B$5:$B$418,$A12,'All measurements'!$C$5:$C$418,F$4,'All measurements'!$D$5:$D$418,"bust")) -> 93.98 | G12: =IF(COUNTIFS('All measurements'!$A$5:$A$418,"Women",'All measurements'!$B$5:$B$418,$A12,'All measurements'!$C$5:$C$418,G$4,'All measurements'!$D$5:$D$418,"bust")=0,"",SUMIFS('All measurements'!$J$5:$J$418,'All measurements'!$A$5:$A$418,"Women",'All measurements'!$B$5:$B$418,$A12,'All measurements'!$C$5:$C$418,G$4,'All measurements'!$D$5:$D$418,"bust")) -> 99.06 | H12: =IF(COUNTIFS('All measurements'!$A$5:$A$418,"Women",'All measurements'!$B$5:$B$418,$A12,'All measurements'!$C$5:$C$418,H$4,'All measurements'!$D$5:$D$418,"bust")=0,"",SUMIFS('All measurements'!$J$5:$J$418,'All measurements'!$A$5:$A$418,"Women",'All measurements'!$B$5:$B$418,$A12,'All measurements'!$C$5:$C$418,H$4,'All measurements'!$D$5:$D$418,"bust")) -> 105.41 | I12: =IF(COUNTIFS('All measurements'!$A$5:$A$418,"Women",'All measurements'!$B$5:$B$418,$A12,'All measurements'!$C$5:$C$418,I$4,'All measurements'!$D$5:$D$418,"bust")=0,"",SUMIFS('All measurements'!$J$5:$J$418,'All measurements'!$A$5:$A$418,"Women",'All measurements'!$B$5:$B$418,$A12,'All measurements'!$C$5:$C$418,I$4,'All measurements'!$D$5:$D$418,"bust")) -> 113.03 | J12: =IF(COUNTIFS('All measurements'!$A$5:$A$418,"Women",'All measurements'!$B$5:$B$418,$A12,'All measurements'!$C$5:$C$418,J$4,'All measurements'!$D$5:$D$418,"bust")=0,"",SUMIFS('All measurements'!$J$5:$J$418,'All measurements'!$A$5:$A$418,"Women",'All measurements'!$B$5:$B$418,$A12,'All measurements'!$C$5:$C$418,J$4,'All measurements'!$D$5:$D$418,"bust")) | K12: =IF(COUNTIFS('All measurements'!$A$5:$A$418,"Women",'All measurements'!$B$5:$B$418,$A12,'All measurements'!$C$5:$C$418,K$4,'All measurements'!$D$5:$D$418,"bust")=0,"",SUMIFS('All measurements'!$J$5:$J$418,'All measurements'!$A$5:$A$418,"Women",'All measurements'!$B$5:$B$418,$A12,'All measurements'!$C$5:$C$418,K$4,'All measurements'!$D$5:$D$418,"bust"))
A13: Red Tape | B13: Sourced | C13: =IF(COUNTIFS('All measurements'!$A$5:$A$418,"Women",'All measurements'!$B$5:$B$418,$A13,'All measurements'!$C$5:$C$418,C$4,'All measurements'!$D$5:$D$418,"bust")=0,"",SUMIFS('All measurements'!$J$5:$J$418,'All measurements'!$A$5:$A$418,"Women",'All measurements'!$B$5:$B$418,$A13,'All measurements'!$C$5:$C$418,C$4,'All measurements'!$D$5:$D$418,"bust")) | D13: =IF(COUNTIFS('All measurements'!$A$5:$A$418,"Women",'All measurements'!$B$5:$B$418,$A13,'All measurements'!$C$5:$C$418,D$4,'All measurements'!$D$5:$D$418,"bust")=0,"",SUMIFS('All measurements'!$J$5:$J$418,'All measurements'!$A$5:$A$418,"Women",'All measurements'!$B$5:$B$418,$A13,'All measurements'!$C$5:$C$418,D$4,'All measurements'!$D$5:$D$418,"bust")) -> 81.28 | E13: =IF(COUNTIFS('All measurements'!$A$5:$A$418,"Women",'All measurements'!$B$5:$B$418,$A13,'All measurements'!$C$5:$C$418,E$4,'All measurements'!$D$5:$D$418,"bust")=0,"",SUMIFS('All measurements'!$J$5:$J$418,'All measurements'!$A$5:$A$418,"Women",'All measurements'!$B$5:$B$418,$A13,'All measurements'!$C$5:$C$418,E$4,'All measurements'!$D$5:$D$418,"bust")) -> 86.36 | F13: =IF(COUNTIFS('All measurements'!$A$5:$A$418,"Women",'All measurements'!$B$5:$B$418,$A13,'All measurements'!$C$5:$C$418,F$4,'All measurements'!$D$5:$D$418,"bust")=0,"",SUMIFS('All measurements'!$J$5:$J$418,'All measurements'!$A$5:$A$418,"Women",'All measurements'!$B$5:$B$418,$A13,'All measurements'!$C$5:$C$418,F$4,'All measurements'!$D$5:$D$418,"bust")) -> 91.44 | G13: =IF(COUNTIFS('All measurements'!$A$5:$A$418,"Women",'All measurements'!$B$5:$B$418,$A13,'All measurements'!$C$5:$C$418,G$4,'All measurements'!$D$5:$D$418,"bust")=0,"",SUMIFS('All measurements'!$J$5:$J$418,'All measurements'!$A$5:$A$418,"Women",'All measurements'!$B$5:$B$418,$A13,'All measurements'!$C$5:$C$418,G$4,'All measurements'!$D$5:$D$418,"bust")) -> 96.52 | H13: =IF(COUNTIFS('All measurements'!$A$5:$A$418,"Women",'All measurements'!$B$5:$B$418,$A13,'All measurements'!$C$5:$C$418,H$4,'All measurements'!$D$5:$D$418,"bust")=0,"",SUMIFS('All measurements'!$J$5:$J$418,'All measurements'!$A$5:$A$418,"Women",'All measurements'!$B$5:$B$418,$A13,'All measurements'!$C$5:$C$418,H$4,'All measurements'!$D$5:$D$418,"bust")) -> 101.6 | I13: =IF(COUNTIFS('All measurements'!$A$5:$A$418,"Women",'All measurements'!$B$5:$B$418,$A13,'All measurements'!$C$5:$C$418,I$4,'All measurements'!$D$5:$D$418,"bust")=0,"",SUMIFS('All measurements'!$J$5:$J$418,'All measurements'!$A$5:$A$418,"Women",'All measurements'!$B$5:$B$418,$A13,'All measurements'!$C$5:$C$418,I$4,'All measurements'!$D$5:$D$418,"bust")) | J13: =IF(COUNTIFS('All measurements'!$A$5:$A$418,"Women",'All measurements'!$B$5:$B$418,$A13,'All measurements'!$C$5:$C$418,J$4,'All measurements'!$D$5:$D$418,"bust")=0,"",SUMIFS('All measurements'!$J$5:$J$418,'All measurements'!$A$5:$A$418,"Women",'All measurements'!$B$5:$B$418,$A13,'All measurements'!$C$5:$C$418,J$4,'All measurements'!$D$5:$D$418,"bust")) | K13: =IF(COUNTIFS('All measurements'!$A$5:$A$418,"Women",'All measurements'!$B$5:$B$418,$A13,'All measurements'!$C$5:$C$418,K$4,'All measurements'!$D$5:$D$418,"bust")=0,"",SUMIFS('All measurements'!$J$5:$J$418,'All measurements'!$A$5:$A$418,"Women",'All measurements'!$B$5:$B$418,$A13,'All measurements'!$C$5:$C$418,K$4,'All measurements'!$D$5:$D$418,"bust"))
A14: The Souled Store | B14: Sourced | C14: =IF(COUNTIFS('All measurements'!$A$5:$A$418,"Women",'All measurements'!$B$5:$B$418,$A14,'All measurements'!$C$5:$C$418,C$4,'All measurements'!$D$5:$D$418,"bust")=0,"",SUMIFS('All measurements'!$J$5:$J$418,'All measurements'!$A$5:$A$418,"Women",'All measurements'!$B$5:$B$418,$A14,'All measurements'!$C$5:$C$418,C$4,'All measurements'!$D$5:$D$418,"bust")) -> 76 | D14: =IF(COUNTIFS('All measurements'!$A$5:$A$418,"Women",'All measurements'!$B$5:$B$418,$A14,'All measurements'!$C$5:$C$418,D$4,'All measurements'!$D$5:$D$418,"bust")=0,"",SUMIFS('All measurements'!$J$5:$J$418,'All measurements'!$A$5:$A$418,"Women",'All measurements'!$B$5:$B$418,$A14,'All measurements'!$C$5:$C$418,D$4,'All measurements'!$D$5:$D$418,"bust")) -> 81 | E14: =IF(COUNTIFS('All measurements'!$A$5:$A$418,"Women",'All measurements'!$B$5:$B$418,$A14,'All measurements'!$C$5:$C$418,E$4,'All measurements'!$D$5:$D$418,"bust")=0,"",SUMIFS('All measurements'!$J$5:$J$418,'All measurements'!$A$5:$A$418,"Women",'All measurements'!$B$5:$B$418,$A14,'All measurements'!$C$5:$C$418,E$4,'All measurements'!$D$5:$D$418,"bust")) -> 86 | F14: =IF(COUNTIFS('All measurements'!$A$5:$A$418,"Women",'All measurements'!$B$5:$B$418,$A14,'All measurements'!$C$5:$C$418,F$4,'All measurements'!$D$5:$D$418,"bust")=0,"",SUMIFS('All measurements'!$J$5:$J$418,'All measurements'!$A$5:$A$418,"Women",'All measurements'!$B$5:$B$418,$A14,'All measurements'!$C$5:$C$418,F$4,'All measurements'!$D$5:$D$418,"bust")) -> 91 | G14: =IF(COUNTIFS('All measurements'!$A$5:$A$418,"Women",'All measurements'!$B$5:$B$418,$A14,'All measurements'!$C$5:$C$418,G$4,'All measurements'!$D$5:$D$418,"bust")=0,"",SUMIFS('All measurements'!$J$5:$J$418,'All measurements'!$A$5:$A$418,"Women",'All measurements'!$B$5:$B$418,$A14,'All measurements'!$C$5:$C$418,G$4,'All measurements'!$D$5:$D$418,"bust")) -> 97 | H14: =IF(COUNTIFS('All measurements'!$A$5:$A$418,"Women",'All measurements'!$B$5:$B$418,$A14,'All measurements'!$C$5:$C$418,H$4,'All measurements'!$D$5:$D$418,"bust")=0,"",SUMIFS('All measurements'!$J$5:$J$418,'All measurements'!$A$5:$A$418,"Women",'All measurements'!$B$5:$B$418,$A14,'All measurements'!$C$5:$C$418,H$4,'All measurements'!$D$5:$D$418,"bust")) -> 101 | I14: =IF(COUNTIFS('All measurements'!$A$5:$A$418,"Women",'All measurements'!$B$5:$B$418,$A14,'All measurements'!$C$5:$C$418,I$4,'All measurements'!$D$5:$D$418,"bust")=0,"",SUMIFS('All measurements'!$J$5:$J$418,'All measurements'!$A$5:$A$418,"Women",'All measurements'!$B$5:$B$418,$A14,'All measurements'!$C$5:$C$418,I$4,'All measurements'!$D$5:$D$418,"bust")) -> 106 | J14: =IF(COUNTIFS('All measurements'!$A$5:$A$418,"Women",'All measurements'!$B$5:$B$418,$A14,'All measurements'!$C$5:$C$418,J$4,'All measurements'!$D$5:$D$418,"bust")=0,"",SUMIFS('All measurements'!$J$5:$J$418,'All measurements'!$A$5:$A$418,"Women",'All measurements'!$B$5:$B$418,$A14,'All measurements'!$C$5:$C$418,J$4,'All measurements'!$D$5:$D$418,"bust")) | K14: =IF(COUNTIFS('All measurements'!$A$5:$A$418,"Women",'All measurements'!$B$5:$B$418,$A14,'All measurements'!$C$5:$C$418,K$4,'All measurements'!$D$5:$D$418,"bust")=0,"",SUMIFS('All measurements'!$J$5:$J$418,'All measurements'!$A$5:$A$418,"Women",'All measurements'!$B$5:$B$418,$A14,'All measurements'!$C$5:$C$418,K$4,'All measurements'!$D$5:$D$418,"bust"))
A15: Uniqlo | B15: Sourced | C15: =IF(COUNTIFS('All measurements'!$A$5:$A$418,"Women",'All measurements'!$B$5:$B$418,$A15,'All measurements'!$C$5:$C$418,C$4,'All measurements'!$D$5:$D$418,"bust")=0,"",SUMIFS('All measurements'!$J$5:$J$418,'All measurements'!$A$5:$A$418,"Women",'All measurements'!$B$5:$B$418,$A15,'All measurements'!$C$5:$C$418,C$4,'All measurements'!$D$5:$D$418,"bust")) | D15: =IF(COUNTIFS('All measurements'!$A$5:$A$418,"Women",'All measurements'!$B$5:$B$418,$A15,'All measurements'!$C$5:$C$418,D$4,'All measurements'!$D$5:$D$418,"bust")=0,"",SUMIFS('All measurements'!$J$5:$J$418,'All measurements'!$A$5:$A$418,"Women",'All measurements'!$B$5:$B$418,$A15,'All measurements'!$C$5:$C$418,D$4,'All measurements'!$D$5:$D$418,"bust")) | E15: =IF(COUNTIFS('All measurements'!$A$5:$A$418,"Women",'All measurements'!$B$5:$B$418,$A15,'All measurements'!$C$5:$C$418,E$4,'All measurements'!$D$5:$D$418,"bust")=0,"",SUMIFS('All measurements'!$J$5:$J$418,'All measurements'!$A$5:$A$418,"Women",'All measurements'!$B$5:$B$418,$A15,'All measurements'!$C$5:$C$418,E$4,'All measurements'!$D$5:$D$418,"bust")) -> 80 | F15: =IF(COUNTIFS('All measurements'!$A$5:$A$418,"Women",'All measurements'!$B$5:$B$418,$A15,'All measurements'!$C$5:$C$418,F$4,'All measurements'!$D$5:$D$418,"bust")=0,"",SUMIFS('All measurements'!$J$5:$J$418,'All measurements'!$A$5:$A$418,"Women",'All measurements'!$B$5:$B$418,$A15,'All measurements'!$C$5:$C$418,F$4,'All measurements'!$D$5:$D$418,"bust")) -> 84 | G15: =IF(COUNTIFS('All measurements'!$A$5:$A$418,"Women",'All measurements'!$B$5:$B$418,$A15,'All measurements'!$C$5:$C$418,G$4,'All measurements'!$D$5:$D$418,"bust")=0,"",SUMIFS('All measurements'!$J$5:$J$418,'All measurements'!$A$5:$A$418,"Women",'All measurements'!$B$5:$B$418,$A15,'All measurements'!$C$5:$C$418,G$4,'All measurements'!$D$5:$D$418,"bust")) -> 88 | H15: =IF(COUNTIFS('All measurements'!$A$5:$A$418,"Women",'All measurements'!$B$5:$B$418,$A15,'All measurements'!$C$5:$C$418,H$4,'All measurements'!$D$5:$D$418,"bust")=0,"",SUMIFS('All measurements'!$J$5:$J$418,'All measurements'!$A$5:$A$418,"Women",'All measurements'!$B$5:$B$418,$A15,'All measurements'!$C$5:$C$418,H$4,'All measurements'!$D$5:$D$418,"bust")) -> 94 | I15: =IF(COUNTIFS('All measurements'!$A$5:$A$418,"Women",'All measurements'!$B$5:$B$418,$A15,'All measurements'!$C$5:$C$418,I$4,'All measurements'!$D$5:$D$418,"bust")=0,"",SUMIFS('All measurements'!$J$5:$J$418,'All measurements'!$A$5:$A$418,"Women",'All measurements'!$B$5:$B$418,$A15,'All measurements'!$C$5:$C$418,I$4,'All measurements'!$D$5:$D$418,"bust")) -> 100 | J15: =IF(COUNTIFS('All measurements'!$A$5:$A$418,"Women",'All measurements'!$B$5:$B$418,$A15,'All measurements'!$C$5:$C$418,J$4,'All measurements'!$D$5:$D$418,"bust")=0,"",SUMIFS('All measurements'!$J$5:$J$418,'All measurements'!$A$5:$A$418,"Women",'All measurements'!$B$5:$B$418,$A15,'All measurements'!$C$5:$C$418,J$4,'All measurements'!$D$5:$D$418,"bust")) -> 106 | K15: =IF(COUNTIFS('All measurements'!$A$5:$A$418,"Women",'All measurements'!$B$5:$B$418,$A15,'All measurements'!$C$5:$C$418,K$4,'All measurements'!$D$5:$D$418,"bust")=0,"",SUMIFS('All measurements'!$J$5:$J$418,'All measurements'!$A$5:$A$418,"Women",'All measurements'!$B$5:$B$418,$A15,'All measurements'!$C$5:$C$418,K$4,'All measurements'!$D$5:$D$418,"bust"))
A16: Westside | B16: Sourced | C16: =IF(COUNTIFS('All measurements'!$A$5:$A$418,"Women",'All measurements'!$B$5:$B$418,$A16,'All measurements'!$C$5:$C$418,C$4,'All measurements'!$D$5:$D$418,"bust")=0,"",SUMIFS('All measurements'!$J$5:$J$418,'All measurements'!$A$5:$A$418,"Women",'All measurements'!$B$5:$B$418,$A16,'All measurements'!$C$5:$C$418,C$4,'All measurements'!$D$5:$D$418,"bust")) -> 77 | D16: =IF(COUNTIFS('All measurements'!$A$5:$A$418,"Women",'All measurements'!$B$5:$B$418,$A16,'All measurements'!$C$5:$C$418,D$4,'All measurements'!$D$5:$D$418,"bust")=0,"",SUMIFS('All measurements'!$J$5:$J$418,'All measurements'!$A$5:$A$418,"Women",'All measurements'!$B$5:$B$418,$A16,'All measurements'!$C$5:$C$418,D$4,'All measurements'!$D$5:$D$418,"bust")) -> 82 | E16: =IF(COUNTIFS('All measurements'!$A$5:$A$418,"Women",'All measurements'!$B$5:$B$418,$A16,'All measurements'!$C$5:$C$418,E$4,'All measurements'!$D$5:$D$418,"bust")=0,"",SUMIFS('All measurements'!$J$5:$J$418,'All measurements'!$A$5:$A$418,"Women",'All measurements'!$B$5:$B$418,$A16,'All measurements'!$C$5:$C$418,E$4,'All measurements'!$D$5:$D$418,"bust")) -> 87 | F16: =IF(COUNTIFS('All measurements'!$A$5:$A$418,"Women",'All measurements'!$B$5:$B$418,$A16,'All measurements'!$C$5:$C$418,F$4,'All measurements'!$D$5:$D$418,"bust")=0,"",SUMIFS('All measurements'!$J$5:$J$418,'All measurements'!$A$5:$A$418,"Women",'All measurements'!$B$5:$B$418,$A16,'All measurements'!$C$5:$C$418,F$4,'All measurements'!$D$5:$D$418,"bust")) -> 92 | G16: =IF(COUNTIFS('All measurements'!$A$5:$A$418,"Women",'All measurements'!$B$5:$B$418,$A16,'All measurements'!$C$5:$C$418,G$4,'All measurements'!$D$5:$D$418,"bust")=0,"",SUMIFS('All measurements'!$J$5:$J$418,'All measurements'!$A$5:$A$418,"Women",'All measurements'!$B$5:$B$418,$A16,'All measurements'!$C$5:$C$418,G$4,'All measurements'!$D$5:$D$418,"bust")) -> 97 | H16: =IF(COUNTIFS('All measurements'!$A$5:$A$418,"Women",'All measurements'!$B$5:$B$418,$A16,'All measurements'!$C$5:$C$418,H$4,'All measurements'!$D$5:$D$418,"bust")=0,"",SUMIFS('All measurements'!$J$5:$J$418,'All measurements'!$A$5:$A$418,"Women",'All measurements'!$B$5:$B$418,$A16,'All measurements'!$C$5:$C$418,H$4,'All measurements'!$D$5:$D$418,"bust")) -> 102 | I16: =IF(COUNTIFS('All measurements'!$A$5:$A$418,"Women",'All measurements'!$B$5:$B$418,$A16,'All measurements'!$C$5:$C$418,I$4,'All measurements'!$D$5:$D$418,"bust")=0,"",SUMIFS('All measurements'!$J$5:$J$418,'All measurements'!$A$5:$A$418,"Women",'All measurements'!$B$5:$B$418,$A16,'All measurements'!$C$5:$C$418,I$4,'All measurements'!$D$5:$D$418,"bust")) -> 107 | J16: =IF(COUNTIFS('All measurements'!$A$5:$A$418,"Women",'All measurements'!$B$5:$B$418,$A16,'All measurements'!$C$5:$C$418,J$4,'All measurements'!$D$5:$D$418,"bust")=0,"",SUMIFS('All measurements'!$J$5:$J$418,'All measurements'!$A$5:$A$418,"Women",'All measurements'!$B$5:$B$418,$A16,'All measurements'!$C$5:$C$418,J$4,'All measurements'!$D$5:$D$418,"bust")) | K16: =IF(COUNTIFS('All measurements'!$A$5:$A$418,"Women",'All measurements'!$B$5:$B$418,$A16,'All measurements'!$C$5:$C$418,K$4,'All measurements'!$D$5:$D$418,"bust")=0,"",SUMIFS('All measurements'!$J$5:$J$418,'All measurements'!$A$5:$A$418,"Women",'All measurements'!$B$5:$B$418,$A16,'All measurements'!$C$5:$C$418,K$4,'All measurements'!$D$5:$D$418,"bust"))
... A18: Zudio | B18: Unverified | C18: =IF(COUNTIFS('All measurements'!$A$5:$A$418,"Women",'All measurements'!$B$5:$B$418,$A18,'All measurements'!$C$5:$C$418,C$4,'All measurements'!$D$5:$D$418,"bust")=0,"",SUMIFS('All measurements'!$J$5:$J$418,'All measurements'!$A$5:$A$418,"Women",'All measurements'!$B$5:$B$418,$A18,'All measurements'!$C$5:$C$418,C$4,'All measurements'!$D$5:$D$418,"bust")) | D18: =IF(COUNTIFS('All measurements'!$A$5:$A$418,"Women",'All measurements'!$B$5:$B$418,$A18,'All measurements'!$C$5:$C$418,D$4,'All measurements'!$D$5:$D$418,"bust")=0,"",SUMIFS('All measurements'!$J$5:$J$418,'All measurements'!$A$5:$A$418,"Women",'All measurements'!$B$5:$B$418,$A18,'All measurements'!$C$5:$C$418,D$4,'All measurements'!$D$5:$D$418,"bust")) -> 81.3 | E18: =IF(COUNTIFS('All measurements'!$A$5:$A$418,"Women",'All measurements'!$B$5:$B$418,$A18,'All measurements'!$C$5:$C$418,E$4,'All measurements'!$D$5:$D$418,"bust")=0,"",SUMIFS('All measurements'!$J$5:$J$418,'All measurements'!$A$5:$A$418,"Women",'All measurements'!$B$5:$B$418,$A18,'All measurements'!$C$5:$C$418,E$4,'All measurements'!$D$5:$D$418,"bust")) -> 86.4 | F18: =IF(COUNTIFS('All measurements'!$A$5:$A$418,"Women",'All measurements'!$B$5:$B$418,$A18,'All measurements'!$C$5:$C$418,F$4,'All measurements'!$D$5:$D$418,"bust")=0,"",SUMIFS('All measurements'!$J$5:$J$418,'All measurements'!$A$5:$A$418,"Women",'All measurements'!$B$5:$B$418,$A18,'All measurements'!$C$5:$C$418,F$4,'All measurements'!$D$5:$D$418,"bust")) -> 91.4 | G18: =IF(COUNTIFS('All measurements'!$A$5:$A$418,"Women",'All measurements'!$B$5:$B$418,$A18,'All measurements'!$C$5:$C$418,G$4,'All measurements'!$D$5:$D$418,"bust")=0,"",SUMIFS('All measurements'!$J$5:$J$418,'All measurements'!$A$5:$A$418,"Women",'All measurements'!$B$5:$B$418,$A18,'All measurements'!$C$5:$C$418,G$4,'All measurements'!$D$5:$D$418,"bust")) -> 96.5 | H18: =IF(COUNTIFS('All measurements'!$A$5:$A$418,"Women",'All measurements'!$B$5:$B$418,$A18,'All measurements'!$C$5:$C$418,H$4,'All measurements'!$D$5:$D$418,"bust")=0,"",SUMIFS('All measurements'!$J$5:$J$418,'All measurements'!$A$5:$A$418,"Women",'All measurements'!$B$5:$B$418,$A18,'All measurements'!$C$5:$C$418,H$4,'All measurements'!$D$5:$D$418,"bust")) -> 101.6 | I18: =IF(COUNTIFS('All measurements'!$A$5:$A$418,"Women",'All measurements'!$B$5:$B$418,$A18,'All measurements'!$C$5:$C$418,I$4,'All measurements'!$D$5:$D$418,"bust")=0,"",SUMIFS('All measurements'!$J$5:$J$418,'All measurements'!$A$5:$A$418,"Women",'All measurements'!$B$5:$B$418,$A18,'All measurements'!$C$5:$C$418,I$4,'All measurements'!$D$5:$D$418,"bust")) -> 106.7 | J18: =IF(COUNTIFS('All measurements'!$A$5:$A$418,"Women",'All measurements'!$B$5:$B$418,$A18,'All measurements'!$C$5:$C$418,J$4,'All measurements'!$D$5:$D$418,"bust")=0,"",SUMIFS('All measurements'!$J$5:$J$418,'All measurements'!$A$5:$A$418,"Women",'All measurements'!$B$5:$B$418,$A18,'All measurements'!$C$5:$C$418,J$4,'All measurements'!$D$5:$D$418,"bust")) | K18: =IF(COUNTIFS('All measurements'!$A$5:$A$418,"Women",'All measurements'!$B$5:$B$418,$A18,'All measurements'!$C$5:$C$418,K$4,'All measurements'!$D$5:$D$418,"bust")=0,"",SUMIFS('All measurements'!$J$5:$J$418,'All measurements'!$A$5:$A$418,"Women",'All measurements'!$B$5:$B$418,$A18,'All measurements'!$C$5:$C$418,K$4,'All measurements'!$D$5:$D$418,"bust"))

Sheet Men chest grid
A1: Men's chest (cm) by brand and size — read side by side
A2: Pulled from 'All measurements' by formula. Blank = that brand doesn't make the size.
A4: Brand | B4: Status | C4: XXS | D4: XS | E4: S | F4: M | G4: L | H4: XL | I4: XXL | J4: 3XL | K4: 4XL
